Workbook
Name Slicer_Department: #N/A
Name Slicer_Gender: #N/A
Name Timeline_Date_of_Joining: #N/A

Sheet Dashboard
A1: EMPLOYEE DETAILS DASHBOARD

Sheet Pivot
A2: Department-wise Employee Count | E2: Country-wise Average Salary Analysis | K2: Salary Status Distribution
A3: Row Labels | B3: Count of Employee ID | E3: Row Labels | F3: Average of Salary | K3: Row Labels | L3: Count of Employee ID
A4: Finance | B4: 21 | E4: Australia | F4: 61609.842 | K4: Good Salary | L4: 57
A5: HR | B5: 22 | E5: Germany | F5: 65897.318 | K5: High Salary | L5: 59
A6: IT | B6: 22 | E6: India | F6: 67654.167 | K6: Low Salary | L6: 24
A7: Marketing | B7: 50 | E7: UK | F7: 62511.045 | K7: Grand Total | L7: 140
A8: Sales | B8: 25 | E8: USA | F8: 68461.565
A9: Grand Total | B9: 140 | E9: Grand Total | F9: 65882.229
L28: Monthly Hiring Trend by Department
A29: Gender Diversity by Department | H29: Department-wise Performance vs Avg Salary
A30: Count of Employee ID | B30: Column Labels | H30: Row Labels | I30: Average of Salary | J30: Average of Performance Rating | L30: Count of Employee ID | M30: Column Labels
A31: Row Labels | B31: Female | C31: Male | D31: Not Specified | E31: Other | F31: Grand Total | H31: Finance | I31: 65617.762 | J31: 2.6666667 | L31: Row Labels | M31: April | N31: August | O31: December | P31: February | Q31: January | R31: July | S31: June | T31: March | U31: May | V31: November | W31: October | X31: September | Y31: Grand Total
A32: Finance | B32: 3 | C32: 2 | D32: 9 | E32: 7 | F32: 21 | H32: HR | I32: 67234.182 | J32: 2.7272727 | L32: Finance | M32: 2 | N32: 2 | O32: 1 | P32: 2 | Q32: 2 | S32: 3 | T32: 1 | U32: 4 | V32: 2 | W32: 2 | Y32: 21
A33: HR | B33: 4 | C33: 6 | D33: 6 | E33: 6 | F33: 22 | H33: IT | I33: 66184.409 | J33: 2.8636364 | L33: HR | M33: 1 | N33: 3 | O33: 2 | Q33: 2 | R33: 3 | T33: 3 | U33: 2 | V33: 2 | W33: 2 | X33: 2 | Y33: 22
A34: IT | B34: 7 | C34: 9 | D34: 4 | E34: 2 | F34: 22 | H34: Marketing | I34: 64847.26 | J34: 3.1 | L34: IT | N34: 1 | O34: 1 | P34: 2 | Q34: 1 | R34: 2 | S34: 1 | T34: 5 | U34: 1 | V34: 2 | W34: 3 | X34: 3 | Y34: 22
A35: Marketing | B35: 11 | C35: 8 | D35: 18 | E35: 13 | F35: 50 | H35: Sales | I35: 66718.68 | J35: 2.84 | L35: Marketing | M35: 4 | N35: 3 | O35: 3 | P35: 4 | Q35: 5 | R35: 5 | S35: 6 | T35: 3 | U35: 4 | V35: 4 | W35: 4 | X35: 5 | Y35: 50
A36: Sales | B36: 8 | C36: 7 | D36: 7 | E36: 3 | F36: 25 | H36: Grand Total | I36: 65882.229 | J36: 2.8928571 | L36: Sales | M36: 4 | N36: 2 | O36: 1 | P36: 3 | Q36: 2 | R36: 4 | S36: 1 | T36: 1 | U36: 3 | W36: 3 | X36: 1 | Y36: 25
A37: Grand Total | B37: 33 | C37: 32 | D37: 44 | E37: 31 | F37: 140 | L37: Grand Total | M37: 11 | N37: 11 | O37: 8 | P37: 11 | Q37: 12 | R37: 14 | S37: 11 | T37: 13 | U37: 14 | V37: 10 | W37: 14 | X37: 11 | Y37: 140
L40: Department | M40: April | N40: August | O40: December | P40: February | Q40: January | R40: July | S40: June | T40: March | U40: May | V40: November | W40: October | X40: September | Y40: Sparkline
L41: Finance | M41: 2 | N41: 2 | O41: 1 | P41: 2 | Q41: 2 | S41: 3 | T41: 1 | U41: 4 | V41: 2 | W41: 2
L42: HR | M42: 1 | N42: 3 | O42: 2 | Q42: 2 | R42: 3 | T42: 3 | U42: 2 | V42: 2 | W42: 2 | X42: 2
L43: IT | N43: 1 | O43: 1 | P43: 2 | Q43: 1 | R43: 2 | S43: 1 | T43: 5 | U43: 1 | V43: 2 | W43: 3 | X43: 3
L44: Marketing | M44: 4 | N44: 3 | O44: 3 | P44: 4 | Q44: 5 | R44: 5 | S44: 6 | T44: 3 | U44: 4 | V44: 4 | W44: 4 | X44: 5
L45: Sales | M45: 4 | N45: 2 | O45: 1 | P45: 3 | Q45: 2 | R45: 4 | S45: 1 | T45: 1 | U45: 3 | W45: 3 | X45: 1
J56: Department-wise Average Employee Tenure
A57: Row Labels | B57: Count of Employee ID | J57: Row Labels | K57: Average of No. of Days with Employer
A58: Marketing | B58: 2 | J58: Finance | K58: 3713.6667
A59: Sales | B59: 3 | J59: HR | K59: 3708.7727
A60: Grand Total | B60: 5 | J60: IT | K60: 3639.7273
J61: Marketing | K61: 3576.04
J62: Sales | K62: 3573
J63: Grand Total | K63: 3627.0071

Sheet Employee Details
A1: Employee ID | B1: Name | C1: First Name | D1: Last Name | E1: Department | F1: Country | G1: Salary | H1: Salary Status | I1: Date of Joining | J1: Month of Joining | K1: No. of Days with Employer | L1: Performance Rating | M1: Gender | N1: Email
A2: EMP1001 | B2: Eve Adams | C2: Eve | D2: Adams | E2: HR | F2: Germany | G2: 54255 | H2: =IF(Sheet1[[#This Row],[Salary]]<40000,"Low Salary",IF(Sheet1[[#This Row],[Salary]]<=70000,"Good Salary","High Salary")) -> Good Salary | I2: 42015 | J2: January | K2: =DATEDIF(Sheet1[[#This Row],[Date of Joining]],TODAY(),"d") -> 4145 | L2: 1 | M2: Other | N2: user106@example.com
A3: EMP1002 | B3: Alice Brown | C3: Alice | D3: Brown | E3: Finance | F3: Germany | G3: 63184 | H3: =IF(Sheet1[[#This Row],[Salary]]<40000,"Low Salary",IF(Sheet1[[#This Row],[Salary]]<=70000,"Good Salary","High Salary")) -> Good Salary | I3: 42022 | J3: January | K3: =DATEDIF(Sheet1[[#This Row],[Date of Joining]],TODAY(),"d") -> 4138 | L3: 2 | M3: Not Specified | N3: user176@example.com
A4: EMP1003 | B4: John Doe | C4: John | D4: Doe | E4: Sales | F4: USA | G4: 94406 | H4: =IF(Sheet1[[#This Row],[Salary]]<40000,"Low Salary",IF(Sheet1[[#This Row],[Salary]]<=70000,"Good Salary","High Salary")) -> High Salary | I4: 42029 | J4: January | K4: =DATEDIF(Sheet1[[#This Row],[Date of Joining]],TODAY(),"d") -> 4131 | L4: 1 | M4: Male | N4: user168@example.com
A5: EMP1004 | B5: Jane Smith | C5: Jane | D5: Smith | E5: Sales | F5: Germany | G5: 64120 | H5: =IF(Sheet1[[#This Row],[Salary]]<40000,"Low Salary",IF(Sheet1[[#This Row],[Salary]]<=70000,"Good Salary","High Salary")) -> Good Salary | I5: 42036 | J5: February | K5: =DATEDIF(Sheet1[[#This Row],[Date of Joining]],TODAY(),"d") -> 4124 | L5: 1 | M5: Male | N5: user49@example.com | S5: Salary
A6: EMP1005 | B6: Alice Brown | C6: Alice | D6: Brown | E6: IT | F6: India | G6: 78421 | H6: =IF(Sheet1[[#This Row],[Salary]]<40000,"Low Salary",IF(Sheet1[[#This Row],[Salary]]<=70000,"Good Salary","High Salary")) -> High Salary | I6: 42043 | J6: February | K6: =DATEDIF(Sheet1[[#This Row],[Date of Joining]],TODAY(),"d") -> 4117 | L6: 2 | M6: Female | N6: user24@example.com
A7: EMP1006 | B7: Sam Wilson | C7: Sam | D7: Wilson | E7: Sales | F7: India | G7: 67721 | H7: =IF(Sheet1[[#This Row],[Salary]]<40000,"Low Salary",IF(Sheet1[[#This Row],[Salary]]<=70000,"Good Salary","High Salary")) -> Good Salary | I7: 42050 | J7: February | K7: =DATEDIF(Sheet1[[#This Row],[Date of Joining]],TODAY(),"d") -> 4110 | L7: 3 | M7: Male | N7: user168@example.com | S7: Mean | T7: 65882.229
A8: EMP1007 | B8: Chris Lee | C8: Chris | D8: Lee | E8: Marketing | F8: India | G8: 35364 | H8: =IF(Sheet1[[#This Row],[Salary]]<40000,"Low Salary",IF(Sheet1[[#This Row],[Salary]]<=70000,"Good Salary","High Salary")) -> Low Salary | I8: 42057 | J8: February | K8: =DATEDIF(Sheet1[[#This Row],[Date of Joining]],TODAY(),"d") -> 4103 | L8: 2 | M8: Other | N8: user26@example.com | S8: Standard Error | T8: 1788.0689
A9: EMP1008 | B9: Alice Brown | C9: Alice | D9: Brown | E9: IT | F9: Germany | G9: 97881 | H9: =IF(Sheet1[[#This Row],[Salary]]<40000,"Low Salary",IF(Sheet1[[#This Row],[Salary]]<=70000,"Good Salary","High Salary")) -> High Salary | I9: 42064 | J9: March | K9: =DATEDIF(Sheet1[[#This Row],[Date of Joining]],TODAY(),"d") -> 4096 | L9: 3 | M9: Female | N9: user25@example.com | S9: Median | T9: 65980.5
A10: EMP1009 | B10: Chris Lee | C10: Chris | D10: Lee | E10: HR | F10: UK | G10: 91846 | H10: =IF(Sheet1[[#This Row],[Salary]]<40000,"Low Salary",IF(Sheet1[[#This Row],[Salary]]<=70000,"Good Salary","High Salary")) -> High Salary | I10: 42071 | J10: March | K10: =DATEDIF(Sheet1[[#This Row],[Date of Joining]],TODAY(),"d") -> 4089 | L10: 3 | M10: Male | N10: user153@example.com | S10: Mode | T10: 65882
A11: EMP1010 | B11: Sam Wilson | C11: Sam | D11: Wilson | E11: Finance | F11: UK | G11: 64247 | H11: =IF(Sheet1[[#This Row],[Salary]]<40000,"Low Salary",IF(Sheet1[[#This Row],[Salary]]<=70000,"Good Salary","High Salary")) -> Good Salary | I11: 42078 | J11: March | K11: =DATEDIF(Sheet1[[#This Row],[Date of Joining]],TODAY(),"d") -> 4082 | L11: 1 | M11: Female | N11: user18@example.com | S11: Standard Deviation | T11: 21156.717 | Z11: Summary for KPI's
A12: EMP1011 | B12: Sam Wilson | C12: Sam | D12: Wilson | E12: IT | F12: USA | G12: 91180 | H12: =IF(Sheet1[[#This Row],[Salary]]<40000,"Low Salary",IF(Sheet1[[#This Row],[Salary]]<=70000,"Good Salary","High Salary")) -> High Salary | I12: 42085 | J12: March | K12: =DATEDIF(Sheet1[[#This Row],[Date of Joining]],TODAY(),"d") -> 4075 | L12: 5 | M12: Male | N12: user1@example.com | S12: Sample Variance | T12: 4.4760666e+08 | V12: Summary | Z12: Total Employees | AA12: =COUNTA(A:A) -> 141
A13: EMP1012 | B13: Bob Johnson | C13: Bob | D13: Johnson | E13: Sales | F13: India | G13: 96418 | H13: =IF(Sheet1[[#This Row],[Salary]]<40000,"Low Salary",IF(Sheet1[[#This Row],[Salary]]<=70000,"Good Salary","High Salary")) -> High Salary | I13: 42092 | J13: March | K13: =DATEDIF(Sheet1[[#This Row],[Date of Joining]],TODAY(),"d") -> 4068 | L13: 5 | M13: Male | N13: user106@example.com | S13: Kurtosis | T13: -1.1994011 | V13: Sum | W13: =SUM(D:D) -> 0 | Z13: Average Salary | AA13: =AVERAGE(G:G) -> 65882.229
A14: EMP1013 | B14: Sam Wilson | C14: Sam | D14: Wilson | E14: Marketing | F14: India | G14: 62158 | H14: =IF(Sheet1[[#This Row],[Salary]]<40000,"Low Salary",IF(Sheet1[[#This Row],[Salary]]<=70000,"Good Salary","High Salary")) -> Good Salary | I14: 42099 | J14: April | K14: =DATEDIF(Sheet1[[#This Row],[Date of Joining]],TODAY(),"d") -> 4061 | L14: 4 | M14: Not Specified | N14: user180@example.com | S14: Skewness | T14: -0.10848119 | V14: Average | W14: =AVERAGE(D:D) -> #DIV/0! | Z14: Total Salary | AA14: =SUM(G:G) -> 9223512
A15: EMP1014 | B15: Jane Smith | C15: Jane | D15: Smith | E15: HR | F15: India | G15: 59894 | H15: =IF(Sheet1[[#This Row],[Salary]]<40000,"Low Salary",IF(Sheet1[[#This Row],[Salary]]<=70000,"Good Salary","High Salary")) -> Good Salary | I15: 42106 | J15: April | K15: =DATEDIF(Sheet1[[#This Row],[Date of Joining]],TODAY(),"d") -> 4054 | L15: 2 | M15: Male | N15: user184@example.com | S15: Range | T15: 69341 | V15: Min | W15: =MIN(D:D) -> 0 | Z15: Highest Salary | AA15: =MAX(G:G) -> 99621
A16: EMP1016 | B16: Bob Johnson | C16: Bob | D16: Johnson | E16: Marketing | F16: Germany | G16: 90271 | H16: =IF(Sheet1[[#This Row],[Salary]]<40000,"Low Salary",IF(Sheet1[[#This Row],[Salary]]<=70000,"Good Salary","High Salary")) -> High Salary | I16: 42120 | J16: April | K16: =DATEDIF(Sheet1[[#This Row],[Date of Joining]],TODAY(),"d") -> 4040 | L16: 3 | M16: Not Specified | N16: user64@example.com | S16: Minimum | T16: 30280 | V16: Count | W16: =COUNT(D:D) -> 0 | Z16: Average Performance Rating | AA16: =AVERAGE(L:L) -> 2.8928571
A17: EMP1017 | B17: Jane Smith | C17: Jane | D17: Smith | E17: Finance | F17: Australia | G17: 41341 | H17: =IF(Sheet1[[#This Row],[Salary]]<40000,"Low Salary",IF(Sheet1[[#This Row],[Salary]]<=70000,"Good Salary","High Salary")) -> Good Salary | I17: 42127 | J17: May | K17: =DATEDIF(Sheet1[[#This Row],[Date of Joining]],TODAY(),"d") -> 4033 | L17: 1 | M17: Other | N17: user38@example.com | S17: Maximum | T17: 99621 | V17: CountA | W17: =COUNTA(D:D) -> 141 | Z17: Longest Serving Employee | AA17: =MAX(K:K) -> 4145
A18: EMP1018 | B18: Alice Brown | C18: Alice | D18: Brown | E18: Finance | F18: UK | G18: 73602 | H18: =IF(Sheet1[[#This Row],[Salary]]<40000,"Low Salary",IF(Sheet1[[#This Row],[Salary]]<=70000,"Good Salary","High Salary")) -> High Salary | I18: 42134 | J18: May | K18: =DATEDIF(Sheet1[[#This Row],[Date of Joining]],TODAY(),"d") -> 4026 | L18: 3 | M18: Not Specified | N18: user96@example.com | S18: Sum | T18: 9223512 | Z18: Employee Count in India | AA18: =COUNTIF(F:F,"India") -> 54
A19: EMP1019 | B19: Eve Adams | C19: Eve | D19: Adams | E19: Marketing | F19: India | G19: 67531 | H19: =IF(Sheet1[[#This Row],[Salary]]<40000,"Low Salary",IF(Sheet1[[#This Row],[Salary]]<=70000,"Good Salary","High Salary")) -> Good Salary | I19: 42141 | J19: May | K19: =DATEDIF(Sheet1[[#This Row],[Date of Joining]],TODAY(),"d") -> 4019 | L19: 5 | M19: Female | N19: user151@example.com | S19: Count | T19: 140
A20: EMP1020 | B20: Jane Smith | C20: Jane | D20: Smith | E20: HR | F20: USA | G20: 65882 | H20: =IF(Sheet1[[#This Row],[Salary]]<40000,"Low Salary",IF(Sheet1[[#This Row],[Salary]]<=70000,"Good Salary","High Salary")) -> Good Salary | I20: 42148 | J20: May | K20: =DATEDIF(Sheet1[[#This Row],[Date of Joining]],TODAY(),"d") -> 4012 | L20: 2 | M20: Other | N20: user200@example.com
A21: EMP1021 | B21: Jane Smith | C21: Jane | D21: Smith | E21: HR | F21: India | G21: 98922 | H21: =IF(Sheet1[[#This Row],[Salary]]<40000,"Low Salary",IF(Sheet1[[#This Row],[Salary]]<=70000,"Good Salary","High Salary")) -> High Salary | I21: 42155 | J21: May | K21: =DATEDIF(Sheet1[[#This Row],[Date of Joining]],TODAY(),"d") -> 4005 | L21: 4 | M21: Not Specified | N21: user77@example.com | V21: Total HR Salary | W21: =SUMIF(E2:E141,"HR",G2:G141) -> 1479152
A22: EMP1022 | B22: Eve Adams | C22: Eve | D22: Adams | E22: Finance | F22: India | G22: 38333 | H22: =IF(Sheet1[[#This Row],[Salary]]<40000,"Low Salary",IF(Sheet1[[#This Row],[Salary]]<=70000,"Good Salary","High Salary")) -> Low Salary | I22: 42162 | J22: June | K22: =DATEDIF(Sheet1[[#This Row],[Date of Joining]],TODAY(),"d") -> 3998 | L22: 5 | M22: Not Specified | N22: user128@example.com | V22: Germany Count | W22: =COUNTIF(F2:F141,"Germany") -> 22
A23: EMP1023 | B23: Alice Brown | C23: Alice | D23: Brown | E23: Marketing | F23: UK | G23: 36515 | H23: =IF(Sheet1[[#This Row],[Salary]]<40000,"Low Salary",IF(Sheet1[[#This Row],[Salary]]<=70000,"Good Salary","High Salary")) -> Low Salary | I23: 42169 | J23: June | K23: =DATEDIF(Sheet1[[#This Row],[Date of Joining]],TODAY(),"d") -> 3991 | L23: 3 | M23: Male | N23: user149@example.com | V23: Average HR Salary | W23: =AVERAGEIF(E2:E141,"HR",G2:G141) -> 67234.182
A24: EMP1024 | B24: Sam Wilson | C24: Sam | D24: Wilson | E24: Finance | F24: India | G24: 91005 | H24: =IF(Sheet1[[#This Row],[Salary]]<40000,"Low Salary",IF(Sheet1[[#This Row],[Salary]]<=70000,"Good Salary","High Salary")) -> High Salary | I24: 42176 | J24: June | K24: =DATEDIF(Sheet1[[#This Row],[Date of Joining]],TODAY(),"d") -> 3984 | L24: 1 | M24: Other | N24: user122@example.com
A25: EMP1025 | B25: Chris Lee | C25: Chris | D25: Lee | E25: Marketing | F25: India | G25: 52272 | H25: =IF(Sheet1[[#This Row],[Salary]]<40000,"Low Salary",IF(Sheet1[[#This Row],[Salary]]<=70000,"Good Salary","High Salary")) -> Good Salary | I25: 42183 | J25: June | K25: =DATEDIF(Sheet1[[#This Row],[Date of Joining]],TODAY(),"d") -> 3977 | L25: 3 | M25: Not Specified | N25: user41@example.com
A26: EMP1026 | B26: Eve Adams | C26: Eve | D26: Adams | E26: Sales | F26: Germany | G26: 76518 | H26: =IF(Sheet1[[#This Row],[Salary]]<40000,"Low Salary",IF(Sheet1[[#This Row],[Salary]]<=70000,"Good Salary","High Salary")) -> High Salary | I26: 42190 | J26: July | K26: =DATEDIF(Sheet1[[#This Row],[Date of Joining]],TODAY(),"d") -> 3970 | L26: 2 | M26: Female | N26: user68@example.com | U26: Average of Salary | V26: =AVERAGE(Sheet1[Salary]) -> 65882.229
A27: EMP1027 | B27: Alice Brown | C27: Alice | D27: Brown | E27: IT | F27: UK | G27: 41448 | H27: =IF(Sheet1[[#This Row],[Salary]]<40000,"Low Salary",IF(Sheet1[[#This Row],[Salary]]<=70000,"Good Salary","High Salary")) -> Good Salary | I27: 42197 | J27: July | K27: =DATEDIF(Sheet1[[#This Row],[Date of Joining]],TODAY(),"d") -> 3963 | L27: 3 | M27: Other | N27: user103@example.com
A28: EMP1028 | B28: John Doe | C28: John | D28: Doe | E28: HR | F28: UK | G28: 49282 | H28: =IF(Sheet1[[#This Row],[Salary]]<40000,"Low Salary",IF(Sheet1[[#This Row],[Salary]]<=70000,"Good Salary","High Salary")) -> Good Salary | I28: 42204 | J28: July | K28: =DATEDIF(Sheet1[[#This Row],[Date of Joining]],TODAY(),"d") -> 3956 | L28: 2 | M28: Female | N28: user135@example.com
A29: EMP1029 | B29: Bob Johnson | C29: Bob | D29: Johnson | E29: Marketing | F29: UK | G29: 92959 | H29: =IF(Sheet1[[#This Row],[Salary]]<40000,"Low Salary",IF(Sheet1[[#This Row],[Salary]]<=70000,"Good Salary","High Salary")) -> High Salary | I29: 42211 | J29: July | K29: =DATEDIF(Sheet1[[#This Row],[Date of Joining]],TODAY(),"d") -> 3949 | L29: 5 | M29: Not Specified | N29: user83@example.com | S29: Date functions
A30: EMP1031 | B30: Eve Adams | C30: Eve | D30: Adams | E30: HR | F30: Germany | G30: 92299 | H30: =IF(Sheet1[[#This Row],[Salary]]<40000,"Low Salary",IF(Sheet1[[#This Row],[Salary]]<=70000,"Good Salary","High Salary")) -> High Salary | I30: 42225 | J30: August | K30: =DATEDIF(Sheet1[[#This Row],[Date of Joining]],TODAY(),"d") -> 3935 | L30: 3 | M30: Male | N30: user143@example.com | S30: Today() | T30: =TODAY() -> 46160
A31: EMP1032 | B31: Sam Wilson | C31: Sam | D31: Wilson | E31: HR | F31: India | G31: 95586 | H31: =IF(Sheet1[[#This Row],[Salary]]<40000,"Low Salary",IF(Sheet1[[#This Row],[Salary]]<=70000,"Good Salary","High Salary")) -> High Salary | I31: 42232 | J31: August | K31: =DATEDIF(Sheet1[[#This Row],[Date of Joining]],TODAY(),"d") -> 3928 | L31: 3 | M31: Other | N31: user190@example.com | S31: Now() | T31: =NOW() -> 46160.564
A32: EMP1033 | B32: Chris Lee | C32: Chris | D32: Lee | E32: Marketing | F32: USA | G32: 95367 | H32: =IF(Sheet1[[#This Row],[Salary]]<40000,"Low Salary",IF(Sheet1[[#This Row],[Salary]]<=70000,"Good Salary","High Salary")) -> High Salary | I32: 42239 | J32: August | K32: =DATEDIF(Sheet1[[#This Row],[Date of Joining]],TODAY(),"d") -> 3921 | L32: 3 | M32: Male | N32: user136@example.com | R32: Year | S32: 42015 | T32: =YEAR(I2) -> 2015
A33: EMP1034 | B33: John Doe | C33: John | D33: Doe | E33: Sales | F33: Australia | G33: 79549 | H33: =IF(Sheet1[[#This Row],[Salary]]<40000,"Low Salary",IF(Sheet1[[#This Row],[Salary]]<=70000,"Good Salary","High Salary")) -> High Salary | I33: 42246 | J33: August | K33: =DATEDIF(Sheet1[[#This Row],[Date of Joining]],TODAY(),"d") -> 3914 | L33: 3 | M33: Not Specified | N33: user198@example.com | R33: Month | S33: 42015 | T33: =MONTH(S33) -> 1
A34: EMP1035 | B34: Alice Brown | C34: Alice | D34: Brown | E34: Marketing | F34: UK | G34: 54463 | H34: =IF(Sheet1[[#This Row],[Salary]]<40000,"Low Salary",IF(Sheet1[[#This Row],[Salary]]<=70000,"Good Salary","High Salary")) -> Good Salary | I34: 42253 | J34: September | K34: =DATEDIF(Sheet1[[#This Row],[Date of Joining]],TODAY(),"d") -> 3907 | L34: 4 | M34: Male | N34: Unknown | R34: Weekday | S34: 42015 | T34: =WEEKDAY(S34) -> 1
A35: EMP1036 | B35: Alice Brown | C35: Alice | D35: Brown | E35: IT | F35: USA | G35: 89781 | H35: =IF(Sheet1[[#This Row],[Salary]]<40000,"Low Salary",IF(Sheet1[[#This Row],[Salary]]<=70000,"Good Salary","High Salary")) -> High Salary | I35: 42260 | J35: September | K35: =DATEDIF(Sheet1[[#This Row],[Date of Joining]],TODAY(),"d") -> 3900 | L35: 3 | M35: Female | N35: user31@example.com
A36: EMP1037 | B36: Alice Brown | C36: Alice | D36: Brown | E36: HR | F36: India | G36: 64796 | H36: =IF(Sheet1[[#This Row],[Salary]]<40000,"Low Salary",IF(Sheet1[[#This Row],[Salary]]<=70000,"Good Salary","High Salary")) -> Good Salary | I36: 42267 | J36: September | K36: =DATEDIF(Sheet1[[#This Row],[Date of Joining]],TODAY(),"d") -> 3893 | L36: 3 | M36: Other | N36: user98@example.com
A37: EMP1038 | B37: John Doe | C37: John | D37: Doe | E37: Marketing | F37: UK | G37: 52093 | H37: =IF(Sheet1[[#This Row],[Salary]]<40000,"Low Salary",IF(Sheet1[[#This Row],[Salary]]<=70000,"Good Salary","High Salary")) -> Good Salary | I37: 42274 | J37: September | K37: =DATEDIF(Sheet1[[#This Row],[Date of Joining]],TODAY(),"d") -> 3886 | L37: 5 | M37: Not Specified | N37: user154@example.com
A38: EMP1039 | B38: Chris Lee | C38: Chris | D38: Lee | E38: HR | F38: UK | G38: 48224 | H38: =IF(Sheet1[[#This Row],[Salary]]<40000,"Low Salary",IF(Sheet1[[#This Row],[Salary]]<=70000,"Good Salary","High Salary")) -> Good Salary | I38: 42281 | J38: October | K38: =DATEDIF(Sheet1[[#This Row],[Date of Joining]],TODAY(),"d") -> 3879 | L38: 3 | M38: Not Specified | N38: user42@example.com
A39: EMP1040 | B39: Bob Johnson | C39: Bob | D39: Johnson | E39: Finance | F39: UK | G39: 65882 | H39: =IF(Sheet1[[#This Row],[Salary]]<40000,"Low Salary",IF(Sheet1[[#This Row],[Salary]]<=70000,"Good Salary","High Salary")) -> Good Salary | I39: 42288 | J39: October | K39: =DATEDIF(Sheet1[[#This Row],[Date of Joining]],TODAY(),"d") -> 3872 | L39: 4 | M39: Female | N39: user89@example.com
A40: EMP1041 | B40: Alice Brown | C40: Alice | D40: Brown | E40: IT | F40: Germany | G40: 33956 | H40: =IF(Sheet1[[#This Row],[Salary]]<40000,"Low Salary",IF(Sheet1[[#This Row],[Salary]]<=70000,"Good Salary","High Salary")) -> Low Salary | I40: 42295 | J40: October | K40: =DATEDIF(Sheet1[[#This Row],[Date of Joining]],TODAY(),"d") -> 3865 | L40: 3 | M40: Not Specified | N40: user47@example.com
...

Sheet Vlookup
A1: Employee ID | B1: Name | C1: First Name | D1: Last Name | E1: Department | F1: Country | G1: Salary | H1: Salary Status | I1: Date of Joining | J1: No. of Days with Employer | K1: Performance Rating | L1: Gender | M1: Email
A2: EMP1001 | B2: =VLOOKUP($A2,'Employee Details'!$A$1:$N$141,2,0) -> Eve Adams | C2: =VLOOKUP($A2,'Employee Details'!$A$1:$N$141,3,0) -> Eve | D2: =VLOOKUP($A2,'Employee Details'!$A$1:$N$141,4,0) -> Adams | E2: =VLOOKUP($A2,'Employee Details'!$A$1:$N$141,5,0) -> HR | F2: =VLOOKUP($A2,'Employee Details'!$A$1:$N$141,6,0) -> Germany | G2: =VLOOKUP($A2,'Employee Details'!$A$1:$N$141,7,0) -> 54255 | H2: =VLOOKUP($A2,'Employee Details'!$A$1:$N$141,8,0) -> Good Salary | I2: =VLOOKUP($A2,'Employee Details'!$A$1:$N$141,9,0) -> 42015 | J2: =VLOOKUP($A2,'Employee Details'!$A$1:$N$141,10,0) -> January | K2: =VLOOKUP($A2,'Employee Details'!$A$1:$N$141,11,0) -> 4145 | L2: =VLOOKUP($A2,'Employee Details'!$A$1:$N$141,12,0) -> 1 | M2: =VLOOKUP($A2,'Employee Details'!$A$1:$N$141,13,0) -> Other
A3: EMP1002 | B3: =VLOOKUP($A3,'Employee Details'!$A$1:$N$141,2,0) -> Alice Brown | C3: =VLOOKUP($A3,'Employee Details'!$A$1:$N$141,3,0) -> Alice | D3: =VLOOKUP($A3,'Employee Details'!$A$1:$N$141,4,0) -> Brown | E3: =VLOOKUP($A3,'Employee Details'!$A$1:$N$141,5,0) -> Finance | F3: =VLOOKUP($A3,'Employee Details'!$A$1:$N$141,6,0) -> Germany | G3: =VLOOKUP($A3,'Employee Details'!$A$1:$N$141,7,0) -> 63184 | H3: =VLOOKUP($A3,'Employee Details'!$A$1:$N$141,8,0) -> Good Salary | I3: =VLOOKUP($A3,'Employee Details'!$A$1:$N$141,9,0) -> 42022 | J3: =VLOOKUP($A3,'Employee Details'!$A$1:$N$141,10,0) -> January | K3: =VLOOKUP($A3,'Employee Details'!$A$1:$N$141,11,0) -> 4138 | L3: =VLOOKUP($A3,'Employee Details'!$A$1:$N$141,12,0) -> 2 | M3: =VLOOKUP($A3,'Employee Details'!$A$1:$N$141,13,0) -> Not Specified
A4: EMP1003 | B4: =VLOOKUP($A4,'Employee Details'!$A$1:$N$141,2,0) -> John Doe | C4: =VLOOKUP($A4,'Employee Details'!$A$1:$N$141,3,0) -> John | D4: =VLOOKUP($A4,'Employee Details'!$A$1:$N$141,4,0) -> Doe | E4: =VLOOKUP($A4,'Employee Details'!$A$1:$N$141,5,0) -> Sales | F4: =VLOOKUP($A4,'Employee Details'!$A$1:$N$141,6,0) -> USA | G4: =VLOOKUP($A4,'Employee Details'!$A$1:$N$141,7,0) -> 94406 | H4: =VLOOKUP($A4,'Employee Details'!$A$1:$N$141,8,0) -> High Salary | I4: =VLOOKUP($A4,'Employee Details'!$A$1:$N$141,9,0) -> 42029 | J4: =VLOOKUP($A4,'Employee Details'!$A$1:$N$141,10,0) -> January | K4: =VLOOKUP($A4,'Employee Details'!$A$1:$N$141,11,0) -> 4131 | L4: =VLOOKUP($A4,'Employee Details'!$A$1:$N$141,12,0) -> 1 | M4: =VLOOKUP($A4,'Employee Details'!$A$1:$N$141,13,0) -> Male
A5: EMP1004 | B5: =VLOOKUP($A5,'Employee Details'!$A$1:$N$141,2,0) -> Jane Smith | C5: =VLOOKUP($A5,'Employee Details'!$A$1:$N$141,3,0) -> Jane | D5: =VLOOKUP($A5,'Employee Details'!$A$1:$N$141,4,0) -> Smith | E5: =VLOOKUP($A5,'Employee Details'!$A$1:$N$141,5,0) -> Sales | F5: =VLOOKUP($A5,'Employee Details'!$A$1:$N$141,6,0) -> Germany | G5: =VLOOKUP($A5,'Employee Details'!$A$1:$N$141,7,0) -> 64120 | H5: =VLOOKUP($A5,'Employee Details'!$A$1:$N$141,8,0) -> Good Salary | I5: =VLOOKUP($A5,'Employee Details'!$A$1:$N$141,9,0) -> 42036 | J5: =VLOOKUP($A5,'Employee Details'!$A$1:$N$141,10,0) -> February | K5: =VLOOKUP($A5,'Employee Details'!$A$1:$N$141,11,0) -> 4124 | L5: =VLOOKUP($A5,'Employee Details'!$A$1:$N$141,12,0) -> 1 | M5: =VLOOKUP($A5,'Employee Details'!$A$1:$N$141,13,0) -> Male
A6: EMP1005 | B6: =VLOOKUP($A6,'Employee Details'!$A$1:$N$141,2,0) -> Alice Brown | C6: =VLOOKUP($A6,'Employee Details'!$A$1:$N$141,3,0) -> Alice | D6: =VLOOKUP($A6,'Employee Details'!$A$1:$N$141,4,0) -> Brown | E6: =VLOOKUP($A6,'Employee Details'!$A$1:$N$141,5,0) -> IT | F6: =VLOOKUP($A6,'Employee Details'!$A$1:$N$141,6,0) -> India | G6: =VLOOKUP($A6,'Employee Details'!$A$1:$N$141,7,0) -> 78421 | H6: =VLOOKUP($A6,'Employee Details'!$A$1:$N$141,8,0) -> High Salary | I6: =VLOOKUP($A6,'Employee Details'!$A$1:$N$141,9,0) -> 42043 | J6: =VLOOKUP($A6,'Employee Details'!$A$1:$N$141,10,0) -> February | K6: =VLOOKUP($A6,'Employee Details'!$A$1:$N$141,11,0) -> 4117 | L6: =VLOOKUP($A6,'Employee Details'!$A$1:$N$141,12,0) -> 2 | M6: =VLOOKUP($A6,'Employee Details'!$A$1:$N$141,13,0) -> Female
A7: EMP1006 | B7: =VLOOKUP($A7,'Employee Details'!$A$1:$N$141,2,0) -> Sam Wilson | C7: =VLOOKUP($A7,'Employee Details'!$A$1:$N$141,3,0) -> Sam | D7: =VLOOKUP($A7,'Employee Details'!$A$1:$N$141,4,0) -> Wilson | E7: =VLOOKUP($A7,'Employee Details'!$A$1:$N$141,5,0) -> Sales | F7: =VLOOKUP($A7,'Employee Details'!$A$1:$N$141,6,0) -> India | G7: =VLOOKUP($A7,'Employee Details'!$A$1:$N$141,7,0) -> 67721 | H7: =VLOOKUP($A7,'Employee Details'!$A$1:$N$141,8,0) -> Good Salary | I7: =VLOOKUP($A7,'Employee Details'!$A$1:$N$141,9,0) -> 42050 | J7: =VLOOKUP($A7,'Employee Details'!$A$1:$N$141,10,0) -> February | K7: =VLOOKUP($A7,'Employee Details'!$A$1:$N$141,11,0) -> 4110 | L7: =VLOOKUP($A7,'Employee Details'!$A$1:$N$141,12,0) -> 3 | M7: =VLOOKUP($A7,'Employee Details'!$A$1:$N$141,13,0) -> Male
A8: EMP1007 | B8: =VLOOKUP($A8,'Employee Details'!$A$1:$N$141,2,0) -> Chris Lee | C8: =VLOOKUP($A8,'Employee Details'!$A$1:$N$141,3,0) -> Chris | D8: =VLOOKUP($A8,'Employee Details'!$A$1:$N$141,4,0) -> Lee | E8: =VLOOKUP($A8,'Employee Details'!$A$1:$N$141,5,0) -> Marketing | F8: =VLOOKUP($A8,'Employee Details'!$A$1:$N$141,6,0) -> India | G8: =VLOOKUP($A8,'Employee Details'!$A$1:$N$141,7,0) -> 35364 | H8: =VLOOKUP($A8,'Employee Details'!$A$1:$N$141,8,0) -> Low Salary | I8: =VLOOKUP($A8,'Employee Details'!$A$1:$N$141,9,0) -> 42057 | J8: =VLOOKUP($A8,'Employee Details'!$A$1:$N$141,10,0) -> February | K8: =VLOOKUP($A8,'Employee Details'!$A$1:$N$141,11,0) -> 4103 | L8: =VLOOKUP($A8,'Employee Details'!$A$1:$N$141,12,0) -> 2 | M8: =VLOOKUP($A8,'Employee Details'!$A$1:$N$141,13,0) -> Other
A9: EMP1008 | B9: =VLOOKUP($A9,'Employee Details'!$A$1:$N$141,2,0) -> Alice Brown | C9: =VLOOKUP($A9,'Employee Details'!$A$1:$N$141,3,0) -> Alice | D9: =VLOOKUP($A9,'Employee Details'!$A$1:$N$141,4,0) -> Brown | E9: =VLOOKUP($A9,'Employee Details'!$A$1:$N$141,5,0) -> IT | F9: =VLOOKUP($A9,'Employee Details'!$A$1:$N$141,6,0) -> Germany | G9: =VLOOKUP($A9,'Employee Details'!$A$1:$N$141,7,0) -> 97881 | H9: =VLOOKUP($A9,'Employee Details'!$A$1:$N$141,8,0) -> High Salary | I9: =VLOOKUP($A9,'Employee Details'!$A$1:$N$141,9,0) -> 42064 | J9: =VLOOKUP($A9,'Employee Details'!$A$1:$N$141,10,0) -> March | K9: =VLOOKUP($A9,'Employee Details'!$A$1:$N$141,11,0) -> 4096 | L9: =VLOOKUP($A9,'Employee Details'!$A$1:$N$141,12,0) -> 3 | M9: =VLOOKUP($A9,'Employee Details'!$A$1:$N$141,13,0) -> Female
A10: EMP1009 | B10: =VLOOKUP($A10,'Employee Details'!$A$1:$N$141,2,0) -> Chris Lee | C10: =VLOOKUP($A10,'Employee Details'!$A$1:$N$141,3,0) -> Chris | D10: =VLOOKUP($A10,'Employee Details'!$A$1:$N$141,4,0) -> Lee | E10: =VLOOKUP($A10,'Employee Details'!$A$1:$N$141,5,0) -> HR | F10: =VLOOKUP($A10,'Employee Details'!$A$1:$N$141,6,0) -> UK | G10: =VLOOKUP($A10,'Employee Details'!$A$1:$N$141,7,0) -> 91846 | H10: =VLOOKUP($A10,'Employee Details'!$A$1:$N$141,8,0) -> High Salary | I10: =VLOOKUP($A10,'Employee Details'!$A$1:$N$141,9,0) -> 42071 | J10: =VLOOKUP($A10,'Employee Details'!$A$1:$N$141,10,0) -> March | K10: =VLOOKUP($A10,'Employee Details'!$A$1:$N$141,11,0) -> 4089 | L10: =VLOOKUP($A10,'Employee Details'!$A$1:$N$141,12,0) -> 3 | M10: =VLOOKUP($A10,'Employee Details'!$A$1:$N$141,13,0) -> Male
A11: EMP1010 | B11: =VLOOKUP($A11,'Employee Details'!$A$1:$N$141,2,0) -> Sam Wilson | C11: =VLOOKUP($A11,'Employee Details'!$A$1:$N$141,3,0) -> Sam | D11: =VLOOKUP($A11,'Employee Details'!$A$1:$N$141,4,0) -> Wilson | E11: =VLOOKUP($A11,'Employee Details'!$A$1:$N$141,5,0) -> Finance | F11: =VLOOKUP($A11,'Employee Details'!$A$1:$N$141,6,0) -> UK | G11: =VLOOKUP($A11,'Employee Details'!$A$1:$N$141,7,0) -> 64247 | H11: =VLOOKUP($A11,'Employee Details'!$A$1:$N$141,8,0) -> Good Salary | I11: =VLOOKUP($A11,'Employee Details'!$A$1:$N$141,9,0) -> 42078 | J11: =VLOOKUP($A11,'Employee Details'!$A$1:$N$141,10,0) -> March | K11: =VLOOKUP($A11,'Employee Details'!$A$1:$N$141,11,0) -> 4082 | L11: =VLOOKUP($A11,'Employee Details'!$A$1:$N$141,12,0) -> 1 | M11: =VLOOKUP($A11,'Employee Details'!$A$1:$N$141,13,0) -> Female
A12: EMP1011 | B12: =VLOOKUP($A12,'Employee Details'!$A$1:$N$141,2,0) -> Sam Wilson | C12: =VLOOKUP($A12,'Employee Details'!$A$1:$N$141,3,0) -> Sam | D12: =VLOOKUP($A12,'Employee Details'!$A$1:$N$141,4,0) -> Wilson | E12: =VLOOKUP($A12,'Employee Details'!$A$1:$N$141,5,0) -> IT | F12: =VLOOKUP($A12,'Employee Details'!$A$1:$N$141,6,0) -> USA | G12: =VLOOKUP($A12,'Employee Details'!$A$1:$N$141,7,0) -> 91180 | H12: =VLOOKUP($A12,'Employee Details'!$A$1:$N$141,8,0) -> High Salary | I12: =VLOOKUP($A12,'Employee Details'!$A$1:$N$141,9,0) -> 42085 | J12: =VLOOKUP($A12,'Employee Details'!$A$1:$N$141,10,0) -> March | K12: =VLOOKUP($A12,'Employee Details'!$A$1:$N$141,11,0) -> 4075 | L12: =VLOOKUP($A12,'Employee Details'!$A$1:$N$141,12,0) -> 5 | M12: =VLOOKUP($A12,'Employee Details'!$A$1:$N$141,13,0) -> Male
A13: EMP1012 | B13: =VLOOKUP($A13,'Employee Details'!$A$1:$N$141,2,0) -> Bob Johnson | C13: =VLOOKUP($A13,'Employee Details'!$A$1:$N$141,3,0) -> Bob | D13: =VLOOKUP($A13,'Employee Details'!$A$1:$N$141,4,0) -> Johnson | E13: =VLOOKUP($A13,'Employee Details'!$A$1:$N$141,5,0) -> Sales | F13: =VLOOKUP($A13,'Employee Details'!$A$1:$N$141,6,0) -> India | G13: =VLOOKUP($A13,'Employee Details'!$A$1:$N$141,7,0) -> 96418 | H13: =VLOOKUP($A13,'Employee Details'!$A$1:$N$141,8,0) -> High Salary | I13: =VLOOKUP($A13,'Employee Details'!$A$1:$N$141,9,0) -> 42092 | J13: =VLOOKUP($A13,'Employee Details'!$A$1:$N$141,10,0) -> March | K13: =VLOOKUP($A13,'Employee Details'!$A$1:$N$141,11,0) -> 4068 | L13: =VLOOKUP($A13,'Employee Details'!$A$1:$N$141,12,0) -> 5 | M13: =VLOOKUP($A13,'Employee Details'!$A$1:$N$141,13,0) -> Male
... A141: EMP1149 | B141: =VLOOKUP($A141,'Employee Details'!$A$1:$N$141,2,0) -> Sam Wilson | C141: =VLOOKUP($A141,'Employee Details'!$A$1:$N$141,3,0) -> Sam | D141: =VLOOKUP($A141,'Employee Details'!$A$1:$N$141,4,0) -> Wilson | E141: =VLOOKUP($A141,'Employee Details'!$A$1:$N$141,5,0) -> Marketing | F141: =VLOOKUP($A141,'Employee Details'!$A$1:$N$141,6,0) -> India | G141: =VLOOKUP($A141,'Employee Details'!$A$1:$N$141,7,0) -> 98475 | H141: =VLOOKUP($A141,'Employee Details'!$A$1:$N$141,8,0) -> High Salary | I141: =VLOOKUP($A141,'Employee Details'!$A$1:$N$141,9,0) -> 43051 | J141: =VLOOKUP($A141,'Employee Details'!$A$1:$N$141,10,0) -> November | K141: =VLOOKUP($A141,'Employee Details'!$A$1:$N$141,11,0) -> 3109 | L141: =VLOOKUP($A141,'Employee Details'!$A$1:$N$141,12,0) -> 5 | M141: =VLOOKUP($A141,'Employee Details'!$A$1:$N$141,13,0) -> Other
